Workbook

Sheet Karbon Entry
A1: Enter in Karbon (Time & Budget → Add Budget Estimate)
A2: Enter ONE budget per recurring series (section 1) and per one-time item (section 3). Section 2 is planning only. Two separate estimates per item: WORK time (e.g. Staff Accountant · Bookkeeping) and REVIEW time (Reviewer · Review). Review is NOT included in Work.
A4: 1. RECURRING WORK – set once on the recurring series; every future item gets it
A5: Client Name | B5: Work Item | C5: Repeats | D5: Work time (h:mm) | E5: Work $ | F5: Review time (h:mm) | G5: Review $ | H5: Work done by
A6: 1402 W Victory LLC | B6: 1099 Quarterly Review (ongoing, after Oct 30) | C6: Quarterly | D6: =ROUND('Recurring Budgets'!F2*60,0)/1440 -> 0.052083333 | E6: =ROUND('Recurring Budgets'!F2*IF(H6="CFO",Assumptions!$B$5,Assumptions!$B$4),0) -> 119 | F6: =ROUND('Recurring Budgets'!G2*60,0)/1440 -> 0 | G6: =ROUND('Recurring Budgets'!G2*Assumptions!$B$5,0) -> 0 | H6: ='Recurring Budgets'!L2 -> Staff
B7: Month End Close | C7: Monthly | D7: =ROUND('Recurring Budgets'!F3*60,0)/1440 -> 0.020833333 | E7: =ROUND('Recurring Budgets'!F3*IF(H7="CFO",Assumptions!$B$5,Assumptions!$B$4),0) -> 48 | F7: =ROUND('Recurring Budgets'!G3*60,0)/1440 -> 0.029166667 | G7: =ROUND('Recurring Budgets'!G3*Assumptions!$B$5,0) -> 175 | H7: ='Recurring Budgets'!L3 -> Staff
A8: 15650 Northsight LLC | B8: 1099 Quarterly Review (ongoing, after Oct 30) | C8: Quarterly | D8: =ROUND('Recurring Budgets'!F4*60,0)/1440 -> 0.052083333 | E8: =ROUND('Recurring Budgets'!F4*IF(H8="CFO",Assumptions!$B$5,Assumptions!$B$4),0) -> 119 | F8: =ROUND('Recurring Budgets'!G4*60,0)/1440 -> 0 | G8: =ROUND('Recurring Budgets'!G4*Assumptions!$B$5,0) -> 0 | H8: ='Recurring Budgets'!L4 -> Staff
B9: Quarter End Close | C9: Quarterly | D9: =ROUND('Recurring Budgets'!F5*60,0)/1440 -> 0.020833333 | E9: =ROUND('Recurring Budgets'!F5*IF(H9="CFO",Assumptions!$B$5,Assumptions!$B$4),0) -> 48 | F9: =ROUND('Recurring Budgets'!G5*60,0)/1440 -> 0.052083333 | G9: =ROUND('Recurring Budgets'!G5*Assumptions!$B$5,0) -> 313 | H9: ='Recurring Budgets'!L5 -> Staff
B10: Quarterly Sales Tax Filing - Onyx Prepares the Returns for Client | C10: Quarterly | D10: =ROUND('Recurring Budgets'!F6*60,0)/1440 -> 0.020833333 | E10: =ROUND('Recurring Budgets'!F6*IF(H10="CFO",Assumptions!$B$5,Assumptions!$B$4),0) -> 48 | F10: =ROUND('Recurring Budgets'!G6*60,0)/1440 -> 0 | G10: =ROUND('Recurring Budgets'!G6*Assumptions!$B$5,0) -> 0 | H10: ='Recurring Budgets'!L6 -> Staff
A11: 1915 NORTH 16TH STREET LLC | B11: Year-End Tax Coordination | C11: Annual | D11: =ROUND('Recurring Budgets'!F7*60,0)/1440 -> 0.041666667 | E11: =ROUND('Recurring Budgets'!F7*IF(H11="CFO",Assumptions!$B$5,Assumptions!$B$4),0) -> 95 | F11: =ROUND('Recurring Budgets'!G7*60,0)/1440 -> 0 | G11: =ROUND('Recurring Budgets'!G7*Assumptions!$B$5,0) -> 0 | H11: ='Recurring Budgets'!L7 -> Staff
A12: 3540 E Boot Track LLC | B12: 1099 Quarterly Review (ongoing, after Oct 30) | C12: Quarterly | D12: =ROUND('Recurring Budgets'!F8*60,0)/1440 -> 0.052083333 | E12: =ROUND('Recurring Budgets'!F8*IF(H12="CFO",Assumptions!$B$5,Assumptions!$B$4),0) -> 119 | F12: =ROUND('Recurring Budgets'!G8*60,0)/1440 -> 0 | G12: =ROUND('Recurring Budgets'!G8*Assumptions!$B$5,0) -> 0 | H12: ='Recurring Budgets'!L8 -> Staff
B13: Month End Close | C13: Monthly | D13: =ROUND('Recurring Budgets'!F9*60,0)/1440 -> 0.09375 | E13: =ROUND('Recurring Budgets'!F9*IF(H13="CFO",Assumptions!$B$5,Assumptions!$B$4),0) -> 214 | F13: =ROUND('Recurring Budgets'!G9*60,0)/1440 -> 0.029166667 | G13: =ROUND('Recurring Budgets'!G9*Assumptions!$B$5,0) -> 175 | H13: ='Recurring Budgets'!L9 -> Staff
A14: 4530 W Flint LLC | B14: 1099 Quarterly Review (ongoing, after Oct 30) | C14: Quarterly | D14: =ROUND('Recurring Budgets'!F10*60,0)/1440 -> 0.052083333 | E14: =ROUND('Recurring Budgets'!F10*IF(H14="CFO",Assumptions!$B$5,Assumptions!$B$4),0) -> 119 | F14: =ROUND('Recurring Budgets'!G10*60,0)/1440 -> 0 | G14: =ROUND('Recurring Budgets'!G10*Assumptions!$B$5,0) -> 0 | H14: ='Recurring Budgets'!L10 -> Staff
B15: Month End Close | C15: Monthly | D15: =ROUND('Recurring Budgets'!F11*60,0)/1440 -> 0.034722222 | E15: =ROUND('Recurring Budgets'!F11*IF(H15="CFO",Assumptions!$B$5,Assumptions!$B$4),0) -> 79 | F15: =ROUND('Recurring Budgets'!G11*60,0)/1440 -> 0.029166667 | G15: =ROUND('Recurring Budgets'!G11*Assumptions!$B$5,0) -> 175 | H15: ='Recurring Budgets'!L11 -> Staff
A16: 7327 Tierra Buena LLC | B16: 1099 Quarterly Review (ongoing, after Oct 30) | C16: Quarterly | D16: =ROUND('Recurring Budgets'!F12*60,0)/1440 -> 0.03125 | E16: =ROUND('Recurring Budgets'!F12*IF(H16="CFO",Assumptions!$B$5,Assumptions!$B$4),0) -> 71 | F16: =ROUND('Recurring Budgets'!G12*60,0)/1440 -> 0 | G16: =ROUND('Recurring Budgets'!G12*Assumptions!$B$5,0) -> 0 | H16: ='Recurring Budgets'!L12 -> Staff
B17: Month End Close | C17: Monthly | D17: =ROUND('Recurring Budgets'!F13*60,0)/1440 -> 0.048611111 | E17: =ROUND('Recurring Budgets'!F13*IF(H17="CFO",Assumptions!$B$5,Assumptions!$B$4),0) -> 111 | F17: =ROUND('Recurring Budgets'!G13*60,0)/1440 -> 0.029166667 | G17: =ROUND('Recurring Budgets'!G13*Assumptions!$B$5,0) -> 175 | H17: ='Recurring Budgets'!L13 -> Staff
A18: 7730 Evans LLC | B18: 1099 Quarterly Review (ongoing, after Oct 30) | C18: Quarterly | D18: =ROUND('Recurring Budgets'!F14*60,0)/1440 -> 0.015972222 | E18: =ROUND('Recurring Budgets'!F14*IF(H18="CFO",Assumptions!$B$5,Assumptions!$B$4),0) -> 36 | F18: =ROUND('Recurring Budgets'!G14*60,0)/1440 -> 0 | G18: =ROUND('Recurring Budgets'!G14*Assumptions!$B$5,0) -> 0 | H18: ='Recurring Budgets'!L14 -> Staff
B19: Month End Close | C19: Monthly | D19: =ROUND('Recurring Budgets'!F15*60,0)/1440 -> 0.03125 | E19: =ROUND('Recurring Budgets'!F15*IF(H19="CFO",Assumptions!$B$5,Assumptions!$B$4),0) -> 71 | F19: =ROUND('Recurring Budgets'!G15*60,0)/1440 -> 0.015972222 | G19: =ROUND('Recurring Budgets'!G15*Assumptions!$B$5,0) -> 96 | H19: ='Recurring Budgets'!L15 -> Staff
A20: 909 MAIN LLC | B20: 1099 Quarterly Review (ongoing, after Oct 30) | C20: Quarterly | D20: =ROUND('Recurring Budgets'!F16*60,0)/1440 -> 0.015972222 | E20: =ROUND('Recurring Budgets'!F16*IF(H20="CFO",Assumptions!$B$5,Assumptions!$B$4),0) -> 36 | F20: =ROUND('Recurring Budgets'!G16*60,0)/1440 -> 0 | G20: =ROUND('Recurring Budgets'!G16*Assumptions!$B$5,0) -> 0 | H20: ='Recurring Budgets'!L16 -> Staff
B21: Month End Close | C21: Monthly | D21: =ROUND('Recurring Budgets'!F17*60,0)/1440 -> 0.052083333 | E21: =ROUND('Recurring Budgets'!F17*IF(H21="CFO",Assumptions!$B$5,Assumptions!$B$4),0) -> 119 | F21: =ROUND('Recurring Budgets'!G17*60,0)/1440 -> 0.020138889 | G21: =ROUND('Recurring Budgets'!G17*Assumptions!$B$5,0) -> 121 | H21: ='Recurring Budgets'!L17 -> Staff
A22: Amerisource HR Consulting Group LLC | B22: 1099 Quarterly Review (ongoing, after Oct 30) | C22: Quarterly | D22: =ROUND('Recurring Budgets'!F18*60,0)/1440 -> 0.03125 | E22: =ROUND('Recurring Budgets'!F18*IF(H22="CFO",Assumptions!$B$5,Assumptions!$B$4),0) -> 71 | F22: =ROUND('Recurring Budgets'!G18*60,0)/1440 -> 0 | G22: =ROUND('Recurring Budgets'!G18*Assumptions!$B$5,0) -> 0 | H22: ='Recurring Budgets'!L18 -> Staff
B23: Adjusting Journal Entry Request | C23: Annual | D23: =ROUND('Recurring Budgets'!F19*60,0)/1440 -> 0.23611111 | E23: =ROUND('Recurring Budgets'!F19*IF(H23="CFO",Assumptions!$B$5,Assumptions!$B$4),0) -> 538 | F23: =ROUND('Recurring Budgets'!G19*60,0)/1440 -> 0 | G23: =ROUND('Recurring Budgets'!G19*Assumptions!$B$5,0) -> 0 | H23: ='Recurring Budgets'!L19 -> Staff
B24: Month End Close | C24: Monthly | D24: =ROUND('Recurring Budgets'!F20*60,0)/1440 -> 0.67361111 | E24: =ROUND('Recurring Budgets'!F20*IF(H24="CFO",Assumptions!$B$5,Assumptions!$B$4),0) -> 1536 | F24: =ROUND('Recurring Budgets'!G20*60,0)/1440 -> 0.041666667 | G24: =ROUND('Recurring Budgets'!G20*Assumptions!$B$5,0) -> 250 | H24: ='Recurring Budgets'!L20 -> Staff
B25: Bookkeeping & Bill Pay | C25: Weekly | D25: =ROUND('Recurring Budgets'!F21*60,0)/1440 -> 0.076388889 | E25: =ROUND('Recurring Budgets'!F21*IF(H25="CFO",Assumptions!$B$5,Assumptions!$B$4),0) -> 174 | F25: =ROUND('Recurring Budgets'!G21*60,0)/1440 -> 0 | G25: =ROUND('Recurring Budgets'!G21*Assumptions!$B$5,0) -> 0 | H25: ='Recurring Budgets'!L21 -> Staff
A26: BSD Contracting LLC | B26: 1099 Quarterly Review (ongoing, after Oct 30) | C26: Quarterly | D26: =ROUND('Recurring Budgets'!F22*60,0)/1440 -> 0.083333333 | E26: =ROUND('Recurring Budgets'!F22*IF(H26="CFO",Assumptions!$B$5,Assumptions!$B$4),0) -> 190 | F26: =ROUND('Recurring Budgets'!G22*60,0)/1440 -> 0 | G26: =ROUND('Recurring Budgets'!G22*Assumptions!$B$5,0) -> 0 | H26: ='Recurring Budgets'!L22 -> Staff
B27: Month End Close | C27: Monthly | D27: =ROUND('Recurring Budgets'!F23*60,0)/1440 -> 0.03125 | E27: =ROUND('Recurring Budgets'!F23*IF(H27="CFO",Assumptions!$B$5,Assumptions!$B$4),0) -> 71 | F27: =ROUND('Recurring Budgets'!G23*60,0)/1440 -> 0.020833333 | G27: =ROUND('Recurring Budgets'!G23*Assumptions!$B$5,0) -> 125 | H27: ='Recurring Budgets'!L23 -> Staff
A28: Barrett Living Trust | B28: Adjusting Journal Entry Request | C28: Annual | D28: =ROUND('Recurring Budgets'!F24*60,0)/1440 -> 0.020833333 | E28: =ROUND('Recurring Budgets'!F24*IF(H28="CFO",Assumptions!$B$5,Assumptions!$B$4),0) -> 48 | F28: =ROUND('Recurring Budgets'!G24*60,0)/1440 -> 0 | G28: =ROUND('Recurring Budgets'!G24*Assumptions!$B$5,0) -> 0 | H28: ='Recurring Budgets'!L24 -> Staff
B29: Month End Close | C29: Monthly | D29: =ROUND('Recurring Budgets'!F25*60,0)/1440 -> 0.11805556 | E29: =ROUND('Recurring Budgets'!F25*IF(H29="CFO",Assumptions!$B$5,Assumptions!$B$4),0) -> 269 | F29: =ROUND('Recurring Budgets'!G25*60,0)/1440 -> 0.045833333 | G29: =ROUND('Recurring Budgets'!G25*Assumptions!$B$5,0) -> 275 | H29: ='Recurring Budgets'!L25 -> Staff
A30: BeckShar Development LLC | B30: 1099 Quarterly Review (ongoing, after Oct 30) | C30: Quarterly | D30: =ROUND('Recurring Budgets'!F26*60,0)/1440 -> 0.03125 | E30: =ROUND('Recurring Budgets'!F26*IF(H30="CFO",Assumptions!$B$5,Assumptions!$B$4),0) -> 71 | F30: =ROUND('Recurring Budgets'!G26*60,0)/1440 -> 0 | G30: =ROUND('Recurring Budgets'!G26*Assumptions!$B$5,0) -> 0 | H30: ='Recurring Budgets'!L26 -> Staff
B31: Month End Close | C31: Monthly | D31: =ROUND('Recurring Budgets'!F27*60,0)/1440 -> 0.28819444 | E31: =ROUND('Recurring Budgets'!F27*IF(H31="CFO",Assumptions!$B$5,Assumptions!$B$4),0) -> 657 | F31: =ROUND('Recurring Budgets'!G27*60,0)/1440 -> 0.033333333 | G31: =ROUND('Recurring Budgets'!G27*Assumptions!$B$5,0) -> 200 | H31: ='Recurring Budgets'!L27 -> Staff
A32: BeckShar Diamond Commercial LLC | B32: 1099 Quarterly Review (ongoing, after Oct 30) | C32: Quarterly | D32: =ROUND('Recurring Budgets'!F28*60,0)/1440 -> 0.03125 | E32: =ROUND('Recurring Budgets'!F28*IF(H32="CFO",Assumptions!$B$5,Assumptions!$B$4),0) -> 71 | F32: =ROUND('Recurring Budgets'!G28*60,0)/1440 -> 0 | G32: =ROUND('Recurring Budgets'!G28*Assumptions!$B$5,0) -> 0 | H32: ='Recurring Budgets'!L28 -> Staff
B33: Month End Close | C33: Monthly | D33: =ROUND('Recurring Budgets'!F29*60,0)/1440 -> 0.017361111 | E33: =ROUND('Recurring Budgets'!F29*IF(H33="CFO",Assumptions!$B$5,Assumptions!$B$4),0) -> 40 | F33: =ROUND('Recurring Budgets'!G29*60,0)/1440 -> 0.020833333 | G33: =ROUND('Recurring Budgets'!G29*Assumptions!$B$5,0) -> 125 | H33: ='Recurring Budgets'!L29 -> Staff
A34: BeckShar LLC | B34: 1099 Quarterly Review (ongoing, after Oct 30) | C34: Quarterly | D34: =ROUND('Recurring Budgets'!F30*60,0)/1440 -> 0.083333333 | E34: =ROUND('Recurring Budgets'!F30*IF(H34="CFO",Assumptions!$B$5,Assumptions!$B$4),0) -> 190 | F34: =ROUND('Recurring Budgets'!G30*60,0)/1440 -> 0 | G34: =ROUND('Recurring Budgets'!G30*Assumptions!$B$5,0) -> 0 | H34: ='Recurring Budgets'!L30 -> Staff
B35: Month End Close | C35: Monthly | D35: =ROUND('Recurring Budgets'!F31*60,0)/1440 -> 0.12152778 | E35: =ROUND('Recurring Budgets'!F31*IF(H35="CFO",Assumptions!$B$5,Assumptions!$B$4),0) -> 277 | F35: =ROUND('Recurring Budgets'!G31*60,0)/1440 -> 0.052083333 | G35: =ROUND('Recurring Budgets'!G31*Assumptions!$B$5,0) -> 313 | H35: ='Recurring Budgets'!L31 -> Staff
A36: Building and Development Professionals LLC | B36: 1099 Quarterly Review (ongoing, after Oct 30) | C36: Quarterly | D36: =ROUND('Recurring Budgets'!F32*60,0)/1440 -> 0.083333333 | E36: =ROUND('Recurring Budgets'!F32*IF(H36="CFO",Assumptions!$B$5,Assumptions!$B$4),0) -> 190 | F36: =ROUND('Recurring Budgets'!G32*60,0)/1440 -> 0 | G36: =ROUND('Recurring Budgets'!G32*Assumptions!$B$5,0) -> 0 | H36: ='Recurring Budgets'!L32 -> Staff
B37: Month End Close | C37: Monthly | D37: =ROUND('Recurring Budgets'!F33*60,0)/1440 -> 0.11458333 | E37: =ROUND('Recurring Budgets'!F33*IF(H37="CFO",Assumptions!$B$5,Assumptions!$B$4),0) -> 688 | F37: =ROUND('Recurring Budgets'!G33*60,0)/1440 -> 0.020833333 | G37: =ROUND('Recurring Budgets'!G33*Assumptions!$B$5,0) -> 125 | H37: ='Recurring Budgets'!L33 -> CFO
A38: Capital Financial LLC | B38: 1099 Quarterly Review (ongoing, after Oct 30) | C38: Quarterly | D38: =ROUND('Recurring Budgets'!F34*60,0)/1440 -> 0.03125 | E38: =ROUND('Recurring Budgets'!F34*IF(H38="CFO",Assumptions!$B$5,Assumptions!$B$4),0) -> 71 | F38: =ROUND('Recurring Budgets'!G34*60,0)/1440 -> 0 | G38: =ROUND('Recurring Budgets'!G34*Assumptions!$B$5,0) -> 0 | H38: ='Recurring Budgets'!L34 -> Staff
B39: Month End Close | C39: Monthly | D39: =ROUND('Recurring Budgets'!F35*60,0)/1440 -> 0.31944444 | E39: =ROUND('Recurring Budgets'!F35*IF(H39="CFO",Assumptions!$B$5,Assumptions!$B$4),0) -> 728 | F39: =ROUND('Recurring Budgets'!G35*60,0)/1440 -> 0.05 | G39: =ROUND('Recurring Budgets'!G35*Assumptions!$B$5,0) -> 300 | H39: ='Recurring Budgets'!L35 -> Staff
A40: Catalpa Industrial Park Inc | B40: 1099 Quarterly Review (ongoing, after Oct 30) | C40: Quarterly | D40: =ROUND('Recurring Budgets'!F36*60,0)/1440 -> 0.083333333 | E40: =ROUND('Recurring Budgets'!F36*IF(H40="CFO",Assumptions!$B$5,Assumptions!$B$4),0) -> 190 | F40: =ROUND('Recurring Budgets'!G36*60,0)/1440 -> 0 | G40: =ROUND('Recurring Budgets'!G36*Assumptions!$B$5,0) -> 0 | H40: ='Recurring Budgets'!L36 -> Staff
B41: Month End Close | C41: Monthly | D41: =ROUND('Recurring Budgets'!F37*60,0)/1440 -> 0.18402778 | E41: =ROUND('Recurring Budgets'!F37*IF(H41="CFO",Assumptions!$B$5,Assumptions!$B$4),0) -> 420 | F41: =ROUND('Recurring Budgets'!G37*60,0)/1440 -> 0.029166667 | G41: =ROUND('Recurring Budgets'!G37*Assumptions!$B$5,0) -> 175 | H41: ='Recurring Budgets'!L37 -> Staff
...

Sheet Read Me
A1: Karbon Budget Hours – Onyx Accounting Group
A2: Built Oct 1, 2026 from the 44 client billing sheets (history to Mar 2026) and the Harvest export (Dec 29, 2025 – Oct 2, 2026).
A3: Budgets are per WORK ITEM, not per person. CFO review is part of month-end but carried as its own number.
A5: HOW TO LOAD INTO KARBON – use the Karbon Entry tab (first tab). Everything else is supporting detail.
A6: 1. Recurring work: open each recurring series in Karbon and enter "Budget (Minutes)" from the Recurring Budgets tab. Future instances inherit it.
A7: 2. Open work already created: use the Open Items (Karbon) tab – one row per open item, matching Karbon Client Name and Work Title exactly.
A8: 3. If Karbon lets you split a budget by role/task, enter Work minutes and CFO Review minutes separately; otherwise enter Budget (Minutes) (the total).
A10: TABS
A11: Assumptions – billing rates, occurrences per month, 1099 sizes and factors, ad hoc reserve. Change a blue cell and every tab updates.
A12: Recurring Budgets – one row per client × recurring work series: budget per occurrence.
A13: Open Items (Karbon) – every open item from the Oct 1 Karbon list with its budget (pulled from the other tabs by formula).
A14: 1099 Oct 30 – the Q3 1099 review cycle, sized by client complexity and Q2 status.
... A39: • Where a client has no separate Payroll / Sales tax / Weekly item, that time is included in its Month End Close budget (the Basis column lists the parts).

Sheet Assumptions
A1: Assumptions (blue cells are inputs)
A3: Billing rates
A4: Staff work rate ($/hr) | B4: 95 | C4: Harvest: Staff Accountant standard rate (Christine/Valentina/Josephine $95).
A5: CFO rate ($/hr) | B5: 250 | C5: Harvest: CFO standard rate (Steven/Lisa Danforth $250).
A7: Occurrences per month
A8: Monthly | B8: 1
A9: Quarterly | B9: 0.33333333 | C9: One quarter-end per 3 months
A10: Weekly | B10: 4.3333333 | C10: 52 weeks ÷ 12
A11: Bi-weekly | B11: 2.1666667 | C11: 26 pay periods ÷ 12
A12: Daily | B12: 30.416667 | C12: Every day incl. weekends (Daily Chase Fraud Review)
A13: Annual | B13: 0.083333333
A14: 1099 | B14: 0.33333333 | C14: Quarterly 1099 review
A16: 1099 full review size (hrs, steps 1–7, Jan–Sep catch-up)
A17: Simple | B17: 0.75 | C17: Valentina's Q2 entries: 0.75h for steps 1–3 on small clients.
A18: Standard | B18: 1.5 | C18: Q2 entries 1.0–1.5h (vendor list prep).
A19: Complex | B19: 4 | C19: 2024 cycle for property/contractor clients ran ~2–6h/yr (billing sheets).
A20: Small property | B20: 2.5 | C20: Josephine: 2h quarterly was overstated by 30–60 min for the small property LLCs (1402 W Victory, 15650 Northsight, 3540 E Boot Track, 7327 Tierra Buena; 4530 W Flint added as same type). Ongoing = 1:15.
A22: 1099 Q2-status factor (Oct 30 cycle)
A23: Completed | B23: 0.5 | C23: Only the Q3 increment is needed.
A24: Partly done (3 of 7) | B24: 0.5 | C24: Josephine: heavy lifting (steps 1–3) was done in Q2 – Q3 only adds new vendors, same as Completed.
A25: Not started | B25: 1 | C25: Full Jan–Sep review.
A26: Not applicable | B26: 0
A27: Excluded (in-house) | B27: 0 | C27: IAG
A29: Ongoing quarterly 1099 (after Oct 30) | B29: 0.5 | C29: Share of a full review needed each later quarter (3 months of new vendors).
A31: Ad hoc reserve (capacity planning, hrs/month)
A32: CFO | B32: 25 | C32: Floor of CFO ad hoc time Feb–Sep 2026 (excl. IAG/ESI). Spikes come from known clients and are budgeted as Large items.
A33: Staff / controller | B33: 10 | C33: Typical staff ad hoc time Feb–Sep 2026; quiet months 3–7h.

Sheet 1099 Oct 30
A1: 1099 Quarterly Review – Oct 30, 2026 cycle
A2: Tier and Q2 status are inputs (blue). Budget = full review size for the tier × Q2-status factor (Assumptions tab).
A4: Client Name | B4: Complexity tier | C4: Q2 status (Karbon) | D4: Full review size (hrs) | E4: Q2-status factor | F4: Oct 30 budget (hrs) | G4: Oct 30 budget (Minutes) | H4: Ongoing quarterly (hrs) | I4: 1099 hrs logged Jul–Sep 2026 (info) | J4: Notes
A5: 1402 W Victory LLC | B5: Small property | C5: Not started | D5: =INDEX(Assumptions!$B$17:$B$20,MATCH(B5,Assumptions!$A$17:$A$20,0)) -> 2.5 | E5: =INDEX(Assumptions!$B$23:$B$27,MATCH(C5,Assumptions!$A$23:$A$27,0)) -> 1 | F5: =D5*E5 -> 2.5 | G5: =ROUND(F5*60,0) -> 150 | H5: =IF(OR(C5="Excluded (in-house)",C5="Not applicable"),0,D5*Assumptions!$B$29) -> 1.25 | I5: 0
A6: 15650 Northsight LLC | B6: Small property | C6: Not started | D6: =INDEX(Assumptions!$B$17:$B$20,MATCH(B6,Assumptions!$A$17:$A$20,0)) -> 2.5 | E6: =INDEX(Assumptions!$B$23:$B$27,MATCH(C6,Assumptions!$A$23:$A$27,0)) -> 1 | F6: =D6*E6 -> 2.5 | G6: =ROUND(F6*60,0) -> 150 | H6: =IF(OR(C6="Excluded (in-house)",C6="Not applicable"),0,D6*Assumptions!$B$29) -> 1.25 | I6: 0
A7: 3540 E Boot Track LLC | B7: Small property | C7: Not started | D7: =INDEX(Assumptions!$B$17:$B$20,MATCH(B7,Assumptions!$A$17:$A$20,0)) -> 2.5 | E7: =INDEX(Assumptions!$B$23:$B$27,MATCH(C7,Assumptions!$A$23:$A$27,0)) -> 1 | F7: =D7*E7 -> 2.5 | G7: =ROUND(F7*60,0) -> 150 | H7: =IF(OR(C7="Excluded (in-house)",C7="Not applicable"),0,D7*Assumptions!$B$29) -> 1.25 | I7: 0
A8: 4530 W Flint LLC | B8: Small property | C8: Not started | D8: =INDEX(Assumptions!$B$17:$B$20,MATCH(B8,Assumptions!$A$17:$A$20,0)) -> 2.5 | E8: =INDEX(Assumptions!$B$23:$B$27,MATCH(C8,Assumptions!$A$23:$A$27,0)) -> 1 | F8: =D8*E8 -> 2.5 | G8: =ROUND(F8*60,0) -> 150 | H8: =IF(OR(C8="Excluded (in-house)",C8="Not applicable"),0,D8*Assumptions!$B$29) -> 1.25 | I8: 0
A9: 7327 Tierra Buena LLC | B9: Standard | C9: Not started | D9: =INDEX(Assumptions!$B$17:$B$20,MATCH(B9,Assumptions!$A$17:$A$20,0)) -> 1.5 | E9: =INDEX(Assumptions!$B$23:$B$27,MATCH(C9,Assumptions!$A$23:$A$27,0)) -> 1 | F9: =D9*E9 -> 1.5 | G9: =ROUND(F9*60,0) -> 90 | H9: =IF(OR(C9="Excluded (in-house)",C9="Not applicable"),0,D9*Assumptions!$B$29) -> 0.75 | I9: 0
A10: 7730 Evans LLC | B10: Simple | C10: Partly done (3 of 7) | D10: =INDEX(Assumptions!$B$17:$B$20,MATCH(B10,Assumptions!$A$17:$A$20,0)) -> 0.75 | E10: =INDEX(Assumptions!$B$23:$B$27,MATCH(C10,Assumptions!$A$23:$A$27,0)) -> 0.5 | F10: =D10*E10 -> 0.375 | G10: =ROUND(F10*60,0) -> 23 | H10: =IF(OR(C10="Excluded (in-house)",C10="Not applicable"),0,D10*Assumptions!$B$29) -> 0.375 | I10: 0.75
A11: 909 MAIN LLC | B11: Simple | C11: Partly done (3 of 7) | D11: =INDEX(Assumptions!$B$17:$B$20,MATCH(B11,Assumptions!$A$17:$A$20,0)) -> 0.75 | E11: =INDEX(Assumptions!$B$23:$B$27,MATCH(C11,Assumptions!$A$23:$A$27,0)) -> 0.5 | F11: =D11*E11 -> 0.375 | G11: =ROUND(F11*60,0) -> 23 | H11: =IF(OR(C11="Excluded (in-house)",C11="Not applicable"),0,D11*Assumptions!$B$29) -> 0.375 | I11: 0.75
A12: Amerisource HR Consulting Group LLC | B12: Standard | C12: Completed | D12: =INDEX(Assumptions!$B$17:$B$20,MATCH(B12,Assumptions!$A$17:$A$20,0)) -> 1.5 | E12: =INDEX(Assumptions!$B$23:$B$27,MATCH(C12,Assumptions!$A$23:$A$27,0)) -> 0.5 | F12: =D12*E12 -> 0.75 | G12: =ROUND(F12*60,0) -> 45 | H12: =IF(OR(C12="Excluded (in-house)",C12="Not applicable"),0,D12*Assumptions!$B$29) -> 0.75 | I12: 4.5 | J12: Q2 completed Jul 21 (dropped off queue after 60 days).
A13: BSD Contracting LLC | B13: Complex | C13: Completed | D13: =INDEX(Assumptions!$B$17:$B$20,MATCH(B13,Assumptions!$A$17:$A$20,0)) -> 4 | E13: =INDEX(Assumptions!$B$23:$B$27,MATCH(C13,Assumptions!$A$23:$A$27,0)) -> 0.5 | F13: =D13*E13 -> 2 | G13: =ROUND(F13*60,0) -> 120 | H13: =IF(OR(C13="Excluded (in-house)",C13="Not applicable"),0,D13*Assumptions!$B$29) -> 2 | I13: 3.8
A14: BeckShar Development LLC | B14: Standard | C14: Completed | D14: =INDEX(Assumptions!$B$17:$B$20,MATCH(B14,Assumptions!$A$17:$A$20,0)) -> 1.5 | E14: =INDEX(Assumptions!$B$23:$B$27,MATCH(C14,Assumptions!$A$23:$A$27,0)) -> 0.5 | F14: =D14*E14 -> 0.75 | G14: =ROUND(F14*60,0) -> 45 | H14: =IF(OR(C14="Excluded (in-house)",C14="Not applicable"),0,D14*Assumptions!$B$29) -> 0.75 | I14: 0.9
A15: BeckShar Diamond Commercial LLC | B15: Standard | C15: Completed | D15: =INDEX(Assumptions!$B$17:$B$20,MATCH(B15,Assumptions!$A$17:$A$20,0)) -> 1.5 | E15: =INDEX(Assumptions!$B$23:$B$27,MATCH(C15,Assumptions!$A$23:$A$27,0)) -> 0.5 | F15: =D15*E15 -> 0.75 | G15: =ROUND(F15*60,0) -> 45 | H15: =IF(OR(C15="Excluded (in-house)",C15="Not applicable"),0,D15*Assumptions!$B$29) -> 0.75 | I15: 1.1
A16: BeckShar LLC | B16: Complex | C16: Completed | D16: =INDEX(Assumptions!$B$17:$B$20,MATCH(B16,Assumptions!$A$17:$A$20,0)) -> 4 | E16: =INDEX(Assumptions!$B$23:$B$27,MATCH(C16,Assumptions!$A$23:$A$27,0)) -> 0.5 | F16: =D16*E16 -> 2 | G16: =ROUND(F16*60,0) -> 120 | H16: =IF(OR(C16="Excluded (in-house)",C16="Not applicable"),0,D16*Assumptions!$B$29) -> 2 | I16: 5.35
A17: Building and Development Professionals LLC | B17: Complex | C17: Not started | D17: =INDEX(Assumptions!$B$17:$B$20,MATCH(B17,Assumptions!$A$17:$A$20,0)) -> 4 | E17: =INDEX(Assumptions!$B$23:$B$27,MATCH(C17,Assumptions!$A$23:$A$27,0)) -> 1 | F17: =D17*E17 -> 4 | G17: =ROUND(F17*60,0) -> 240 | H17: =IF(OR(C17="Excluded (in-house)",C17="Not applicable"),0,D17*Assumptions!$B$29) -> 2 | I17: 0
A18: Capital Financial LLC | B18: Standard | C18: Completed | D18: =INDEX(Assumptions!$B$17:$B$20,MATCH(B18,Assumptions!$A$17:$A$20,0)) -> 1.5 | E18: =INDEX(Assumptions!$B$23:$B$27,MATCH(C18,Assumptions!$A$23:$A$27,0)) -> 0.5 | F18: =D18*E18 -> 0.75 | G18: =ROUND(F18*60,0) -> 45 | H18: =IF(OR(C18="Excluded (in-house)",C18="Not applicable"),0,D18*Assumptions!$B$29) -> 0.75 | I18: 3 | J18: Q2 showed 8 of 8 but marked Cancelled – treated as completed (confirm).
A19: Catalpa Industrial Park Inc | B19: Complex | C19: Not started | D19: =INDEX(Assumptions!$B$17:$B$20,MATCH(B19,Assumptions!$A$17:$A$20,0)) -> 4 | E19: =INDEX(Assumptions!$B$23:$B$27,MATCH(C19,Assumptions!$A$23:$A$27,0)) -> 1 | F19: =D19*E19 -> 4 | G19: =ROUND(F19*60,0) -> 240 | H19: =IF(OR(C19="Excluded (in-house)",C19="Not applicable"),0,D19*Assumptions!$B$29) -> 2 | I19: 0
A20: Desert Quail Creative Classroom LLC | B20: Simple | C20: Not started | D20: =INDEX(Assumptions!$B$17:$B$20,MATCH(B20,Assumptions!$A$17:$A$20,0)) -> 0.75 | E20: =INDEX(Assumptions!$B$23:$B$27,MATCH(C20,Assumptions!$A$23:$A$27,0)) -> 1 | F20: =D20*E20 -> 0.75 | G20: =ROUND(F20*60,0) -> 45 | H20: =IF(OR(C20="Excluded (in-house)",C20="Not applicable"),0,D20*Assumptions!$B$29) -> 0.375 | I20: 0
A21: Educational Services Holdings LLC | B21: Standard | C21: Partly done (3 of 7) | D21: =INDEX(Assumptions!$B$17:$B$20,MATCH(B21,Assumptions!$A$17:$A$20,0)) -> 1.5 | E21: =INDEX(Assumptions!$B$23:$B$27,MATCH(C21,Assumptions!$A$23:$A$27,0)) -> 0.5 | F21: =D21*E21 -> 0.75 | G21: =ROUND(F21*60,0) -> 45 | H21: =IF(OR(C21="Excluded (in-house)",C21="Not applicable"),0,D21*Assumptions!$B$29) -> 0.75 | I21: 1.25
A22: Eight Eleven LLC | B22: Complex | C22: Partly done (3 of 7) | D22: =INDEX(Assumptions!$B$17:$B$20,MATCH(B22,Assumptions!$A$17:$A$20,0)) -> 4 | E22: =INDEX(Assumptions!$B$23:$B$27,MATCH(C22,Assumptions!$A$23:$A$27,0)) -> 0.5 | F22: =D22*E22 -> 2 | G22: =ROUND(F22*60,0) -> 120 | H22: =IF(OR(C22="Excluded (in-house)",C22="Not applicable"),0,D22*Assumptions!$B$29) -> 2 | I22: 7 | J22: Q2 waiting for client (steps 4–6) – may carry over.
A23: FiveOliver LLC | B23: Complex | C23: Not started | D23: =INDEX(Assumptions!$B$17:$B$20,MATCH(B23,Assumptions!$A$17:$A$20,0)) -> 4 | E23: =INDEX(Assumptions!$B$23:$B$27,MATCH(C23,Assumptions!$A$23:$A$27,0)) -> 1 | F23: =D23*E23 -> 4 | G23: =ROUND(F23*60,0) -> 240 | H23: =IF(OR(C23="Excluded (in-house)",C23="Not applicable"),0,D23*Assumptions!$B$29) -> 2 | I23: 0
A24: GAV Enterprises Inc | B24: Standard | C24: Not started | D24: =INDEX(Assumptions!$B$17:$B$20,MATCH(B24,Assumptions!$A$17:$A$20,0)) -> 1.5 | E24: =INDEX(Assumptions!$B$23:$B$27,MATCH(C24,Assumptions!$A$23:$A$27,0)) -> 1 | F24: =D24*E24 -> 1.5 | G24: =ROUND(F24*60,0) -> 90 | H24: =IF(OR(C24="Excluded (in-house)",C24="Not applicable"),0,D24*Assumptions!$B$29) -> 0.75 | I24: 1 | J24: Karbon 0 of 7, but 1.0h logged Sept 25.
A25: International Alliance Group LLC | B25: Standard | C25: Excluded (in-house) | D25: =INDEX(Assumptions!$B$17:$B$20,MATCH(B25,Assumptions!$A$17:$A$20,0)) -> 1.5 | E25: =INDEX(Assumptions!$B$23:$B$27,MATCH(C25,Assumptions!$A$23:$A$27,0)) -> 0 | F25: =D25*E25 -> 0 | G25: =ROUND(F25*60,0) -> 0 | H25: =IF(OR(C25="Excluded (in-house)",C25="Not applicable"),0,D25*Assumptions!$B$29) -> 0 | I25: 10 | J25: In-house – excluded.
A26: KAMM ADGT LLC | B26: Simple | C26: Completed | D26: =INDEX(Assumptions!$B$17:$B$20,MATCH(B26,Assumptions!$A$17:$A$20,0)) -> 0.75 | E26: =INDEX(Assumptions!$B$23:$B$27,MATCH(C26,Assumptions!$A$23:$A$27,0)) -> 0.5 | F26: =D26*E26 -> 0.375 | G26: =ROUND(F26*60,0) -> 23 | H26: =IF(OR(C26="Excluded (in-house)",C26="Not applicable"),0,D26*Assumptions!$B$29) -> 0.375 | I26: 1
A27: Little Moo's LLC | B27: Simple | C27: Partly done (3 of 7) | D27: =INDEX(Assumptions!$B$17:$B$20,MATCH(B27,Assumptions!$A$17:$A$20,0)) -> 0.75 | E27: =INDEX(Assumptions!$B$23:$B$27,MATCH(C27,Assumptions!$A$23:$A$27,0)) -> 0.5 | F27: =D27*E27 -> 0.375 | G27: =ROUND(F27*60,0) -> 23 | H27: =IF(OR(C27="Excluded (in-house)",C27="Not applicable"),0,D27*Assumptions!$B$29) -> 0.375 | I27: 0.75
A28: Midwest Contracting Inc | B28: Complex | C28: Partly done (3 of 7) | D28: =INDEX(Assumptions!$B$17:$B$20,MATCH(B28,Assumptions!$A$17:$A$20,0)) -> 4 | E28: =INDEX(Assumptions!$B$23:$B$27,MATCH(C28,Assumptions!$A$23:$A$27,0)) -> 0.5 | F28: =D28*E28 -> 2 | G28: =ROUND(F28*60,0) -> 120 | H28: =IF(OR(C28="Excluded (in-house)",C28="Not applicable"),0,D28*Assumptions!$B$29) -> 2 | I28: 8 | J28: Q2 waiting for client (steps 4–6) – may carry over.
A29: Mohrschladt Capital LP | B29: Standard | C29: Not started | D29: =INDEX(Assumptions!$B$17:$B$20,MATCH(B29,Assumptions!$A$17:$A$20,0)) -> 1.5 | E29: =INDEX(Assumptions!$B$23:$B$27,MATCH(C29,Assumptions!$A$23:$A$27,0)) -> 1 | F29: =D29*E29 -> 1.5 | G29: =ROUND(F29*60,0) -> 90 | H29: =IF(OR(C29="Excluded (in-house)",C29="Not applicable"),0,D29*Assumptions!$B$29) -> 0.75 | I29: 0
A30: Mohrschladt Howarth Associates Inc | B30: Complex | C30: Not started | D30: =INDEX(Assumptions!$B$17:$B$20,MATCH(B30,Assumptions!$A$17:$A$20,0)) -> 4 | E30: =INDEX(Assumptions!$B$23:$B$27,MATCH(C30,Assumptions!$A$23:$A$27,0)) -> 1 | F30: =D30*E30 -> 4 | G30: =ROUND(F30*60,0) -> 240 | H30: =IF(OR(C30="Excluded (in-house)",C30="Not applicable"),0,D30*Assumptions!$B$29) -> 2 | I30: 0
A31: Mountain Trade Supply Inc | B31: Complex | C31: Not started | D31: =INDEX(Assumptions!$B$17:$B$20,MATCH(B31,Assumptions!$A$17:$A$20,0)) -> 4 | E31: =INDEX(Assumptions!$B$23:$B$27,MATCH(C31,Assumptions!$A$23:$A$27,0)) -> 1 | F31: =D31*E31 -> 4 | G31: =ROUND(F31*60,0) -> 240 | H31: =IF(OR(C31="Excluded (in-house)",C31="Not applicable"),0,D31*Assumptions!$B$29) -> 2 | I31: 0 | J31: No Q2 item – new for Q3.
A32: Newport Classic Cars LLC | B32: Standard | C32: Not started | D32: =INDEX(Assumptions!$B$17:$B$20,MATCH(B32,Assumptions!$A$17:$A$20,0)) -> 1.5 | E32: =INDEX(Assumptions!$B$23:$B$27,MATCH(C32,Assumptions!$A$23:$A$27,0)) -> 1 | F32: =D32*E32 -> 1.5 | G32: =ROUND(F32*60,0) -> 90 | H32: =IF(OR(C32="Excluded (in-house)",C32="Not applicable"),0,D32*Assumptions!$B$29) -> 0.75 | I32: 0
A33: Obsidian Real Estate LLC | B33: Complex | C33: Not started | D33: =INDEX(Assumptions!$B$17:$B$20,MATCH(B33,Assumptions!$A$17:$A$20,0)) -> 4 | E33: =INDEX(Assumptions!$B$23:$B$27,MATCH(C33,Assumptions!$A$23:$A$27,0)) -> 1 | F33: =D33*E33 -> 4 | G33: =ROUND(F33*60,0) -> 240 | H33: =IF(OR(C33="Excluded (in-house)",C33="Not applicable"),0,D33*Assumptions!$B$29) -> 2 | I33: 0
A34: Preferred Renovations LLC | B34: Complex | C34: Completed | D34: =INDEX(Assumptions!$B$17:$B$20,MATCH(B34,Assumptions!$A$17:$A$20,0)) -> 4 | E34: =INDEX(Assumptions!$B$23:$B$27,MATCH(C34,Assumptions!$A$23:$A$27,0)) -> 0.5 | F34: =D34*E34 -> 2 | G34: =ROUND(F34*60,0) -> 120 | H34: =IF(OR(C34="Excluded (in-house)",C34="Not applicable"),0,D34*Assumptions!$B$29) -> 2 | I34: 0 | J34: Q2 completed Jul 22 (dropped off queue after 60 days).
A35: Prestige Arms Worldwide | B35: Simple | C35: Not started | D35: =INDEX(Assumptions!$B$17:$B$20,MATCH(B35,Assumptions!$A$17:$A$20,0)) -> 0.75 | E35: =INDEX(Assumptions!$B$23:$B$27,MATCH(C35,Assumptions!$A$23:$A$27,0)) -> 1 | F35: =D35*E35 -> 0.75 | G35: =ROUND(F35*60,0) -> 45 | H35: =IF(OR(C35="Excluded (in-house)",C35="Not applicable"),0,D35*Assumptions!$B$29) -> 0.375 | I35: 0
A36: Prime Solar USA LLC | B36: Standard | C36: Not started | D36: =INDEX(Assumptions!$B$17:$B$20,MATCH(B36,Assumptions!$A$17:$A$20,0)) -> 1.5 | E36: =INDEX(Assumptions!$B$23:$B$27,MATCH(C36,Assumptions!$A$23:$A$27,0)) -> 1 | F36: =D36*E36 -> 1.5 | G36: =ROUND(F36*60,0) -> 90 | H36: =IF(OR(C36="Excluded (in-house)",C36="Not applicable"),0,D36*Assumptions!$B$29) -> 0.75 | I36: 2.5 | J36: Karbon 0 of 7, but 2.5h logged Aug 27–28 (vendor list prepared).
A37: Rancho Industrial Park Inc | B37: Complex | C37: Not started | D37: =INDEX(Assumptions!$B$17:$B$20,MATCH(B37,Assumptions!$A$17:$A$20,0)) -> 4 | E37: =INDEX(Assumptions!$B$23:$B$27,MATCH(C37,Assumptions!$A$23:$A$27,0)) -> 1 | F37: =D37*E37 -> 4 | G37: =ROUND(F37*60,0) -> 240 | H37: =IF(OR(C37="Excluded (in-house)",C37="Not applicable"),0,D37*Assumptions!$B$29) -> 2 | I37: 0
A38: SW Art Glass Inc | B38: Simple | C38: Not applicable | D38: =INDEX(Assumptions!$B$17:$B$20,MATCH(B38,Assumptions!$A$17:$A$20,0)) -> 0.75 | E38: =INDEX(Assumptions!$B$23:$B$27,MATCH(C38,Assumptions!$A$23:$A$27,0)) -> 0 | F38: =D38*E38 -> 0 | G38: =ROUND(F38*60,0) -> 0 | H38: =IF(OR(C38="Excluded (in-house)",C38="Not applicable"),0,D38*Assumptions!$B$29) -> 0 | I38: 0
A39: Southwest Rents Inc | B39: Complex | C39: Not started | D39: =INDEX(Assumptions!$B$17:$B$20,MATCH(B39,Assumptions!$A$17:$A$20,0)) -> 4 | E39: =INDEX(Assumptions!$B$23:$B$27,MATCH(C39,Assumptions!$A$23:$A$27,0)) -> 1 | F39: =D39*E39 -> 4 | G39: =ROUND(F39*60,0) -> 240 | H39: =IF(OR(C39="Excluded (in-house)",C39="Not applicable"),0,D39*Assumptions!$B$29) -> 2 | I39: 0
A40: T5 Family Holdings LLC | B40: Simple | C40: Partly done (3 of 7) | D40: =INDEX(Assumptions!$B$17:$B$20,MATCH(B40,Assumptions!$A$17:$A$20,0)) -> 0.75 | E40: =INDEX(Assumptions!$B$23:$B$27,MATCH(C40,Assumptions!$A$23:$A$27,0)) -> 0.5 | F40: =D40*E40 -> 0.375 | G40: =ROUND(F40*60,0) -> 23 | H40: =IF(OR(C40="Excluded (in-house)",C40="Not applicable"),0,D40*Assumptions!$B$29) -> 0.375 | I40: 0.75
A41: Tavasci Brothers Motorsports LLC | B41: Simple | C41: Partly done (3 of 7) | D41: =INDEX(Assumptions!$B$17:$B$20,MATCH(B41,Assumptions!$A$17:$A$20,0)) -> 0.75 | E41: =INDEX(Assumptions!$B$23:$B$27,MATCH(C41,Assumptions!$A$23:$A$27,0)) -> 0.5 | F41: =D41*E41 -> 0.375 | G41: =ROUND(F41*60,0) -> 23 | H41: =IF(OR(C41="Excluded (in-house)",C41="Not applicable"),0,D41*Assumptions!$B$29) -> 0.375 | I41: 0.75
...

Sheet Recurring Budgets
A1: Lookup key | B1: Client Name | C1: Work Type | D1: Work Item (recurring series) | E1: Repeats | F1: Work (hrs / occurrence) | G1: CFO Review (hrs / occurrence) | H1: Total (hrs / occurrence) | I1: Budget (Minutes) | J1: Work (Minutes) | K1: CFO Review (Minutes) | L1: Work rate | M1: Budget (USD) | N1: Monthly equivalent – Work (hrs) | O1: Monthly equivalent – CFO Review (hrs) | P1: Confidence | Q1: Basis / notes | R1: Baseline months used
A2: 1402 W Victory LLC|1099|1099 Quarterly Review|1099 | B2: 1402 W Victory LLC | C2: 1099 | D2: 1099 Quarterly Review | E2: 1099 | F2: =IFERROR(INDEX('1099 Oct 30'!$H$5:$H$45,MATCH(B2,'1099 Oct 30'!$A$5:$A$45,0)),0) -> 1.25 | G2: 0 | H2: =F2+G2 -> 1.25 | I2: =ROUND(H2*60,0) -> 75 | J2: =ROUND(F2*60,0) -> 75 | K2: =ROUND(G2*60,0) -> 0 | L2: Staff | M2: =F2*IF(L2="CFO",Assumptions!$B$5,Assumptions!$B$4)+G2*Assumptions!$B$5 -> 118.75 | N2: =F2*INDEX(Assumptions!$B$8:$B$14,MATCH(E2,Assumptions!$A$8:$A$14,0)) -> 0.41666667 | O2: =G2*INDEX(Assumptions!$B$8:$B$14,MATCH(E2,Assumptions!$A$8:$A$14,0)) -> 0 | P2: Estimate | Q2: 1099 tier Small property: ongoing quarterly review (half a full review). See 1099 tab for the Oct 30 cycle. | R2: Settled from 2026-06 (2026-06 – 2026-09)
A3: 1402 W Victory LLC|Monthly Financials|Month End Close|Monthly | B3: 1402 W Victory LLC | C3: Monthly Financials | D3: Month End Close | E3: Monthly | F3: 0.5 | G3: 0.7 | H3: =F3+G3 -> 1.2 | I3: =ROUND(H3*60,0) -> 72 | J3: =ROUND(F3*60,0) -> 30 | K3: =ROUND(G3*60,0) -> 42 | L3: Staff | M3: =F3*IF(L3="CFO",Assumptions!$B$5,Assumptions!$B$4)+G3*Assumptions!$B$5 -> 222.5 | N3: =F3*INDEX(Assumptions!$B$8:$B$14,MATCH(E3,Assumptions!$A$8:$A$14,0)) -> 0.5 | O3: =G3*INDEX(Assumptions!$B$8:$B$14,MATCH(E3,Assumptions!$A$8:$A$14,0)) -> 0.7 | P3: High | Q3: Includes Month-end 0.7. Review = median of 7 closes reviewed in Harvest (0.70h). | R3: Settled from 2026-06 (2026-06 – 2026-09)
A4: 15650 Northsight LLC|1099|1099 Quarterly Review|1099 | B4: 15650 Northsight LLC | C4: 1099 | D4: 1099 Quarterly Review | E4: 1099 | F4: =IFERROR(INDEX('1099 Oct 30'!$H$5:$H$45,MATCH(B4,'1099 Oct 30'!$A$5:$A$45,0)),0) -> 1.25 | G4: 0 | H4: =F4+G4 -> 1.25 | I4: =ROUND(H4*60,0) -> 75 | J4: =ROUND(F4*60,0) -> 75 | K4: =ROUND(G4*60,0) -> 0 | L4: Staff | M4: =F4*IF(L4="CFO",Assumptions!$B$5,Assumptions!$B$4)+G4*Assumptions!$B$5 -> 118.75 | N4: =F4*INDEX(Assumptions!$B$8:$B$14,MATCH(E4,Assumptions!$A$8:$A$14,0)) -> 0.41666667 | O4: =G4*INDEX(Assumptions!$B$8:$B$14,MATCH(E4,Assumptions!$A$8:$A$14,0)) -> 0 | P4: Estimate | Q4: 1099 tier Small property: ongoing quarterly review (half a full review). See 1099 tab for the Oct 30 cycle. | R4: Quarterly client – average of Apr–Sep 2026 (2026-04 – 2026-09)
A5: 15650 Northsight LLC|Accounting|Quarter End Close|Quarterly | B5: 15650 Northsight LLC | C5: Accounting | D5: Quarter End Close | E5: Quarterly | F5: 0.5 | G5: 1.25 | H5: =F5+G5 -> 1.75 | I5: =ROUND(H5*60,0) -> 105 | J5: =ROUND(F5*60,0) -> 30 | K5: =ROUND(G5*60,0) -> 75 | L5: Staff | M5: =F5*IF(L5="CFO",Assumptions!$B$5,Assumptions!$B$4)+G5*Assumptions!$B$5 -> 360 | N5: =F5*INDEX(Assumptions!$B$8:$B$14,MATCH(E5,Assumptions!$A$8:$A$14,0)) -> 0.16666667 | O5: =G5*INDEX(Assumptions!$B$8:$B$14,MATCH(E5,Assumptions!$A$8:$A$14,0)) -> 0.41666667 | P5: High | Q5: Includes Month-end 0.5. Review = 1.25h as logged (only 2 reviewed close(s) in Harvest – check). | R5: Quarterly client – average of Apr–Sep 2026 (2026-04 – 2026-09)
A6: 15650 Northsight LLC|Sales tax|Quarterly Sales Tax Filing - Onyx Prepares the Returns for Client|Quarterly | B6: 15650 Northsight LLC | C6: Sales tax | D6: Quarterly Sales Tax Filing - Onyx Prepares the Returns for Client | E6: Quarterly | F6: 0.5 | G6: 0 | H6: =F6+G6 -> 0.5 | I6: =ROUND(H6*60,0) -> 30 | J6: =ROUND(F6*60,0) -> 30 | K6: =ROUND(G6*60,0) -> 0 | L6: Staff | M6: =F6*IF(L6="CFO",Assumptions!$B$5,Assumptions!$B$4)+G6*Assumptions!$B$5 -> 47.5 | N6: =F6*INDEX(Assumptions!$B$8:$B$14,MATCH(E6,Assumptions!$A$8:$A$14,0)) -> 0.16666667 | O6: =G6*INDEX(Assumptions!$B$8:$B$14,MATCH(E6,Assumptions!$A$8:$A$14,0)) -> 0 | P6: Estimate | Q6: Sales tax time × 3 (quarterly filing). Little logged time – minimum applied. | R6: Quarterly client – average of Apr–Sep 2026 (2026-04 – 2026-09)
A7: 1915 NORTH 16TH STREET LLC|Default|Year-End Tax Coordination|Annual | B7: 1915 NORTH 16TH STREET LLC | C7: Default | D7: Year-End Tax Coordination | E7: Annual | F7: 1 | G7: 0 | H7: =F7+G7 -> 1 | I7: =ROUND(H7*60,0) -> 60 | J7: =ROUND(F7*60,0) -> 60 | K7: =ROUND(G7*60,0) -> 0 | L7: Staff | M7: =F7*IF(L7="CFO",Assumptions!$B$5,Assumptions!$B$4)+G7*Assumptions!$B$5 -> 95 | N7: =F7*INDEX(Assumptions!$B$8:$B$14,MATCH(E7,Assumptions!$A$8:$A$14,0)) -> 0.083333333 | O7: =G7*INDEX(Assumptions!$B$8:$B$14,MATCH(E7,Assumptions!$A$8:$A$14,0)) -> 0 | P7: Estimate | Q7: No year-end hours logged in the last 12 months – placeholder 1.0h. | R7: No recent recurring hours
A8: 3540 E Boot Track LLC|1099|1099 Quarterly Review|1099 | B8: 3540 E Boot Track LLC | C8: 1099 | D8: 1099 Quarterly Review | E8: 1099 | F8: =IFERROR(INDEX('1099 Oct 30'!$H$5:$H$45,MATCH(B8,'1099 Oct 30'!$A$5:$A$45,0)),0) -> 1.25 | G8: 0 | H8: =F8+G8 -> 1.25 | I8: =ROUND(H8*60,0) -> 75 | J8: =ROUND(F8*60,0) -> 75 | K8: =ROUND(G8*60,0) -> 0 | L8: Staff | M8: =F8*IF(L8="CFO",Assumptions!$B$5,Assumptions!$B$4)+G8*Assumptions!$B$5 -> 118.75 | N8: =F8*INDEX(Assumptions!$B$8:$B$14,MATCH(E8,Assumptions!$A$8:$A$14,0)) -> 0.41666667 | O8: =G8*INDEX(Assumptions!$B$8:$B$14,MATCH(E8,Assumptions!$A$8:$A$14,0)) -> 0 | P8: Estimate | Q8: 1099 tier Small property: ongoing quarterly review (half a full review). See 1099 tab for the Oct 30 cycle. | R8: Settled from 2026-07 (2026-07 – 2026-09)
A9: 3540 E Boot Track LLC|Monthly Financials|Month End Close|Monthly | B9: 3540 E Boot Track LLC | C9: Monthly Financials | D9: Month End Close | E9: Monthly | F9: 2.25 | G9: 0.7 | H9: =F9+G9 -> 2.95 | I9: =ROUND(H9*60,0) -> 177 | J9: =ROUND(F9*60,0) -> 135 | K9: =ROUND(G9*60,0) -> 42 | L9: Staff | M9: =F9*IF(L9="CFO",Assumptions!$B$5,Assumptions!$B$4)+G9*Assumptions!$B$5 -> 388.75 | N9: =F9*INDEX(Assumptions!$B$8:$B$14,MATCH(E9,Assumptions!$A$8:$A$14,0)) -> 2.25 | O9: =G9*INDEX(Assumptions!$B$8:$B$14,MATCH(E9,Assumptions!$A$8:$A$14,0)) -> 0.7 | P9: High | Q9: Includes Month-end 2.4. Review = median of 7 closes reviewed in Harvest (0.70h). | R9: Settled from 2026-07 (2026-07 – 2026-09)
A10: 4530 W Flint LLC|1099|1099 Quarterly Review|1099 | B10: 4530 W Flint LLC | C10: 1099 | D10: 1099 Quarterly Review | E10: 1099 | F10: =IFERROR(INDEX('1099 Oct 30'!$H$5:$H$45,MATCH(B10,'1099 Oct 30'!$A$5:$A$45,0)),0) -> 1.25 | G10: 0 | H10: =F10+G10 -> 1.25 | I10: =ROUND(H10*60,0) -> 75 | J10: =ROUND(F10*60,0) -> 75 | K10: =ROUND(G10*60,0) -> 0 | L10: Staff | M10: =F10*IF(L10="CFO",Assumptions!$B$5,Assumptions!$B$4)+G10*Assumptions!$B$5 -> 118.75 | N10: =F10*INDEX(Assumptions!$B$8:$B$14,MATCH(E10,Assumptions!$A$8:$A$14,0)) -> 0.41666667 | O10: =G10*INDEX(Assumptions!$B$8:$B$14,MATCH(E10,Assumptions!$A$8:$A$14,0)) -> 0 | P10: Estimate | Q10: 1099 tier Small property: ongoing quarterly review (half a full review). See 1099 tab for the Oct 30 cycle. | R10: Settled from 2026-02 (2026-02 – 2026-09)
A11: 4530 W Flint LLC|Monthly Financials|Month End Close|Monthly | B11: 4530 W Flint LLC | C11: Monthly Financials | D11: Month End Close | E11: Monthly | F11: 0.8333 | G11: 0.7 | H11: =F11+G11 -> 1.5333 | I11: =ROUND(H11*60,0) -> 92 | J11: =ROUND(F11*60,0) -> 50 | K11: =ROUND(G11*60,0) -> 42 | L11: Staff | M11: =F11*IF(L11="CFO",Assumptions!$B$5,Assumptions!$B$4)+G11*Assumptions!$B$5 -> 254.1635 | N11: =F11*INDEX(Assumptions!$B$8:$B$14,MATCH(E11,Assumptions!$A$8:$A$14,0)) -> 0.8333 | O11: =G11*INDEX(Assumptions!$B$8:$B$14,MATCH(E11,Assumptions!$A$8:$A$14,0)) -> 0.7 | P11: High | Q11: Includes Month-end 0.8. Review = median of 7 closes reviewed in Harvest (0.70h). | R11: Settled from 2026-02 (2026-02 – 2026-09)
A12: 7327 Tierra Buena LLC|1099|1099 Quarterly Review|1099 | B12: 7327 Tierra Buena LLC | C12: 1099 | D12: 1099 Quarterly Review | E12: 1099 | F12: =IFERROR(INDEX('1099 Oct 30'!$H$5:$H$45,MATCH(B12,'1099 Oct 30'!$A$5:$A$45,0)),0) -> 0.75 | G12: 0 | H12: =F12+G12 -> 0.75 | I12: =ROUND(H12*60,0) -> 45 | J12: =ROUND(F12*60,0) -> 45 | K12: =ROUND(G12*60,0) -> 0 | L12: Staff | M12: =F12*IF(L12="CFO",Assumptions!$B$5,Assumptions!$B$4)+G12*Assumptions!$B$5 -> 71.25 | N12: =F12*INDEX(Assumptions!$B$8:$B$14,MATCH(E12,Assumptions!$A$8:$A$14,0)) -> 0.25 | O12: =G12*INDEX(Assumptions!$B$8:$B$14,MATCH(E12,Assumptions!$A$8:$A$14,0)) -> 0 | P12: Estimate | Q12: 1099 tier Standard: ongoing quarterly review (half a full review). See 1099 tab for the Oct 30 cycle. | R12: Settled from 2026-02 (2026-02 – 2026-09)
A13: 7327 Tierra Buena LLC|Monthly Financials|Month End Close|Monthly | B13: 7327 Tierra Buena LLC | C13: Monthly Financials | D13: Month End Close | E13: Monthly | F13: 1.1667 | G13: 0.7 | H13: =F13+G13 -> 1.8667 | I13: =ROUND(H13*60,0) -> 112 | J13: =ROUND(F13*60,0) -> 70 | K13: =ROUND(G13*60,0) -> 42 | L13: Staff | M13: =F13*IF(L13="CFO",Assumptions!$B$5,Assumptions!$B$4)+G13*Assumptions!$B$5 -> 285.8365 | N13: =F13*INDEX(Assumptions!$B$8:$B$14,MATCH(E13,Assumptions!$A$8:$A$14,0)) -> 1.1667 | O13: =G13*INDEX(Assumptions!$B$8:$B$14,MATCH(E13,Assumptions!$A$8:$A$14,0)) -> 0.7 | P13: High | Q13: Includes Month-end 1.3. Review = median of 7 closes reviewed in Harvest (0.70h). | R13: Settled from 2026-02 (2026-02 – 2026-09)
A14: 7730 Evans LLC|1099|1099 Quarterly Review|1099 | B14: 7730 Evans LLC | C14: 1099 | D14: 1099 Quarterly Review | E14: 1099 | F14: =IFERROR(INDEX('1099 Oct 30'!$H$5:$H$45,MATCH(B14,'1099 Oct 30'!$A$5:$A$45,0)),0) -> 0.375 | G14: 0 | H14: =F14+G14 -> 0.375 | I14: =ROUND(H14*60,0) -> 23 | J14: =ROUND(F14*60,0) -> 23 | K14: =ROUND(G14*60,0) -> 0 | L14: Staff | M14: =F14*IF(L14="CFO",Assumptions!$B$5,Assumptions!$B$4)+G14*Assumptions!$B$5 -> 35.625 | N14: =F14*INDEX(Assumptions!$B$8:$B$14,MATCH(E14,Assumptions!$A$8:$A$14,0)) -> 0.125 | O14: =G14*INDEX(Assumptions!$B$8:$B$14,MATCH(E14,Assumptions!$A$8:$A$14,0)) -> 0 | P14: Estimate | Q14: 1099 tier Simple: ongoing quarterly review (half a full review). See 1099 tab for the Oct 30 cycle. | R14: Settled from 2026-04 (2026-04 – 2026-09)
A15: 7730 Evans LLC|Monthly Financials|Month End Close|Monthly | B15: 7730 Evans LLC | C15: Monthly Financials | D15: Month End Close | E15: Monthly | F15: 0.75 | G15: 0.3833 | H15: =F15+G15 -> 1.1333 | I15: =ROUND(H15*60,0) -> 68 | J15: =ROUND(F15*60,0) -> 45 | K15: =ROUND(G15*60,0) -> 23 | L15: Staff | M15: =F15*IF(L15="CFO",Assumptions!$B$5,Assumptions!$B$4)+G15*Assumptions!$B$5 -> 167.075 | N15: =F15*INDEX(Assumptions!$B$8:$B$14,MATCH(E15,Assumptions!$A$8:$A$14,0)) -> 0.75 | O15: =G15*INDEX(Assumptions!$B$8:$B$14,MATCH(E15,Assumptions!$A$8:$A$14,0)) -> 0.3833 | P15: Medium | Q15: Josephine's Apr–May 2026 closes + allowance for a new person (Valentina's hours not used). Review = median of 8 closes reviewed in Harvest (0.38h). | R15: Settled from 2026-04 (2026-04 – 2026-09)
A16: 909 MAIN LLC|1099|1099 Quarterly Review|1099 | B16: 909 MAIN LLC | C16: 1099 | D16: 1099 Quarterly Review | E16: 1099 | F16: =IFERROR(INDEX('1099 Oct 30'!$H$5:$H$45,MATCH(B16,'1099 Oct 30'!$A$5:$A$45,0)),0) -> 0.375 | G16: 0 | H16: =F16+G16 -> 0.375 | I16: =ROUND(H16*60,0) -> 23 | J16: =ROUND(F16*60,0) -> 23 | K16: =ROUND(G16*60,0) -> 0 | L16: Staff | M16: =F16*IF(L16="CFO",Assumptions!$B$5,Assumptions!$B$4)+G16*Assumptions!$B$5 -> 35.625 | N16: =F16*INDEX(Assumptions!$B$8:$B$14,MATCH(E16,Assumptions!$A$8:$A$14,0)) -> 0.125 | O16: =G16*INDEX(Assumptions!$B$8:$B$14,MATCH(E16,Assumptions!$A$8:$A$14,0)) -> 0 | P16: Provisional | Q16: 1099 tier Simple: ongoing quarterly review (half a full review). See 1099 tab for the Oct 30 cycle. Will become an Airbnb – provisional. Revisit once it converts. | R16: Settled from 2026-06 (2026-06 – 2026-09)
A17: 909 MAIN LLC|Monthly Financials|Month End Close|Monthly | B17: 909 MAIN LLC | C17: Monthly Financials | D17: Month End Close | E17: Monthly | F17: 1.25 | G17: 0.4833 | H17: =F17+G17 -> 1.7333 | I17: =ROUND(H17*60,0) -> 104 | J17: =ROUND(F17*60,0) -> 75 | K17: =ROUND(G17*60,0) -> 29 | L17: Staff | M17: =F17*IF(L17="CFO",Assumptions!$B$5,Assumptions!$B$4)+G17*Assumptions!$B$5 -> 239.575 | N17: =F17*INDEX(Assumptions!$B$8:$B$14,MATCH(E17,Assumptions!$A$8:$A$14,0)) -> 1.25 | O17: =G17*INDEX(Assumptions!$B$8:$B$14,MATCH(E17,Assumptions!$A$8:$A$14,0)) -> 0.4833 | P17: Provisional | Q17: Josephine's Apr–May 2026 closes + allowance for a new person (Valentina's hours not used). Will become an Airbnb – provisional. Revisit once it converts. Review = median of 8 closes reviewed in Harvest (0.48h). | R17: Settled from 2026-06 (2026-06 – 2026-09)
A18: Amerisource HR Consulting Group LLC|1099|1099 Quarterly Review|1099 | B18: Amerisource HR Consulting Group LLC | C18: 1099 | D18: 1099 Quarterly Review | E18: 1099 | F18: =IFERROR(INDEX('1099 Oct 30'!$H$5:$H$45,MATCH(B18,'1099 Oct 30'!$A$5:$A$45,0)),0) -> 0.75 | G18: 0 | H18: =F18+G18 -> 0.75 | I18: =ROUND(H18*60,0) -> 45 | J18: =ROUND(F18*60,0) -> 45 | K18: =ROUND(G18*60,0) -> 0 | L18: Staff | M18: =F18*IF(L18="CFO",Assumptions!$B$5,Assumptions!$B$4)+G18*Assumptions!$B$5 -> 71.25 | N18: =F18*INDEX(Assumptions!$B$8:$B$14,MATCH(E18,Assumptions!$A$8:$A$14,0)) -> 0.25 | O18: =G18*INDEX(Assumptions!$B$8:$B$14,MATCH(E18,Assumptions!$A$8:$A$14,0)) -> 0 | P18: Estimate | Q18: 1099 tier Standard: ongoing quarterly review (half a full review). See 1099 tab for the Oct 30 cycle. | R18: Settled from 2026-07 (2026-07 – 2026-09)
A19: Amerisource HR Consulting Group LLC|Year-end review|Adjusting Journal Entry Request|Annual | B19: Amerisource HR Consulting Group LLC | C19: Year-end review | D19: Adjusting Journal Entry Request | E19: Annual | F19: 5.6667 | G19: 0 | H19: =F19+G19 -> 5.6667 | I19: =ROUND(H19*60,0) -> 340 | J19: =ROUND(F19*60,0) -> 340 | K19: =ROUND(G19*60,0) -> 0 | L19: Staff | M19: =F19*IF(L19="CFO",Assumptions!$B$5,Assumptions!$B$4)+G19*Assumptions!$B$5 -> 538.3365 | N19: =F19*INDEX(Assumptions!$B$8:$B$14,MATCH(E19,Assumptions!$A$8:$A$14,0)) -> 0.472225 | O19: =G19*INDEX(Assumptions!$B$8:$B$14,MATCH(E19,Assumptions!$A$8:$A$14,0)) -> 0 | P19: High | Q19: Year-end/tax hours Oct 2025–Sep 2026 (5.6h). | R19: Settled from 2026-07 (2026-07 – 2026-09)
A20: Amerisource HR Consulting Group LLC|Monthly Financials|Month End Close|Monthly | B20: Amerisource HR Consulting Group LLC | C20: Monthly Financials | D20: Month End Close | E20: Monthly | F20: 16.1667 | G20: 1 | H20: =F20+G20 -> 17.1667 | I20: =ROUND(H20*60,0) -> 1030 | J20: =ROUND(F20*60,0) -> 970 | K20: =ROUND(G20*60,0) -> 60 | L20: Staff | M20: =F20*IF(L20="CFO",Assumptions!$B$5,Assumptions!$B$4)+G20*Assumptions!$B$5 -> 1785.8365 | N20: =F20*INDEX(Assumptions!$B$8:$B$14,MATCH(E20,Assumptions!$A$8:$A$14,0)) -> 16.1667 | O20: =G20*INDEX(Assumptions!$B$8:$B$14,MATCH(E20,Assumptions!$A$8:$A$14,0)) -> 1 | P20: High | Q20: Includes Month-end 5.0, Payroll 11.7, CFO advisory 0.2. Review = median of 4 closes reviewed in Harvest (1.00h). | R20: Settled from 2026-07 (2026-07 – 2026-09)
A21: Amerisource HR Consulting Group LLC|Bookkeeping|Bookkeeping & Bill Pay|Weekly | B21: Amerisource HR Consulting Group LLC | C21: Bookkeeping | D21: Bookkeeping & Bill Pay | E21: Weekly | F21: 1.8333 | G21: 0 | H21: =F21+G21 -> 1.8333 | I21: =ROUND(H21*60,0) -> 110 | J21: =ROUND(F21*60,0) -> 110 | K21: =ROUND(G21*60,0) -> 0 | L21: Staff | M21: =F21*IF(L21="CFO",Assumptions!$B$5,Assumptions!$B$4)+G21*Assumptions!$B$5 -> 174.1635 | N21: =F21*INDEX(Assumptions!$B$8:$B$14,MATCH(E21,Assumptions!$A$8:$A$14,0)) -> 7.9443 | O21: =G21*INDEX(Assumptions!$B$8:$B$14,MATCH(E21,Assumptions!$A$8:$A$14,0)) -> 0 | P21: High | Q21: Weekly bookkeeping/settlement time ÷ weeks per month. | R21: Settled from 2026-07 (2026-07 – 2026-09)
A22: BSD Contracting LLC|1099|1099 Quarterly Review|1099 | B22: BSD Contracting LLC | C22: 1099 | D22: 1099 Quarterly Review | E22: 1099 | F22: =IFERROR(INDEX('1099 Oct 30'!$H$5:$H$45,MATCH(B22,'1099 Oct 30'!$A$5:$A$45,0)),0) -> 2 | G22: 0 | H22: =F22+G22 -> 2 | I22: =ROUND(H22*60,0) -> 120 | J22: =ROUND(F22*60,0) -> 120 | K22: =ROUND(G22*60,0) -> 0 | L22: Staff | M22: =F22*IF(L22="CFO",Assumptions!$B$5,Assumptions!$B$4)+G22*Assumptions!$B$5 -> 190 | N22: =F22*INDEX(Assumptions!$B$8:$B$14,MATCH(E22,Assumptions!$A$8:$A$14,0)) -> 0.66666667 | O22: =G22*INDEX(Assumptions!$B$8:$B$14,MATCH(E22,Assumptions!$A$8:$A$14,0)) -> 0 | P22: Estimate | Q22: 1099 tier Complex: ongoing quarterly review (half a full review). See 1099 tab for the Oct 30 cycle. | R22: Settled from 2026-04 (2026-04 – 2026-09)
A23: BSD Contracting LLC|Monthly Financials|Month End Close|Monthly | B23: BSD Contracting LLC | C23: Monthly Financials | D23: Month End Close | E23: Monthly | F23: 0.75 | G23: 0.5 | H23: =F23+G23 -> 1.25 | I23: =ROUND(H23*60,0) -> 75 | J23: =ROUND(F23*60,0) -> 45 | K23: =ROUND(G23*60,0) -> 30 | L23: Staff | M23: =F23*IF(L23="CFO",Assumptions!$B$5,Assumptions!$B$4)+G23*Assumptions!$B$5 -> 196.25 | N23: =F23*INDEX(Assumptions!$B$8:$B$14,MATCH(E23,Assumptions!$A$8:$A$14,0)) -> 0.75 | O23: =G23*INDEX(Assumptions!$B$8:$B$14,MATCH(E23,Assumptions!$A$8:$A$14,0)) -> 0.5 | P23: High | Q23: Includes Month-end 0.7, Payroll 0.4. Review = median of 4 closes reviewed in Harvest (0.50h). | R23: Settled from 2026-04 (2026-04 – 2026-09)
A24: Barrett Living Trust|Year-end review|Adjusting Journal Entry Request|Annual | B24: Barrett Living Trust | C24: Year-end review | D24: Adjusting Journal Entry Request | E24: Annual | F24: 0.5 | G24: 0 | H24: =F24+G24 -> 0.5 | I24: =ROUND(H24*60,0) -> 30 | J24: =ROUND(F24*60,0) -> 30 | K24: =ROUND(G24*60,0) -> 0 | L24: Staff | M24: =F24*IF(L24="CFO",Assumptions!$B$5,Assumptions!$B$4)+G24*Assumptions!$B$5 -> 47.5 | N24: =F24*INDEX(Assumptions!$B$8:$B$14,MATCH(E24,Assumptions!$A$8:$A$14,0)) -> 0.041666667 | O24: =G24*INDEX(Assumptions!$B$8:$B$14,MATCH(E24,Assumptions!$A$8:$A$14,0)) -> 0 | P24: High | Q24: Year-end/tax hours Oct 2025–Sep 2026 (0.5h). | R24: Not settled by rule – median of last 6 months (2026-04 – 2026-09)
A25: Barrett Living Trust|Accounting|Month End Close|Monthly | B25: Barrett Living Trust | C25: Accounting | D25: Month End Close | E25: Monthly | F25: 2.8333 | G25: 1.1 | H25: =F25+G25 -> 3.9333 | I25: =ROUND(H25*60,0) -> 236 | J25: =ROUND(F25*60,0) -> 170 | K25: =ROUND(G25*60,0) -> 66 | L25: Staff | M25: =F25*IF(L25="CFO",Assumptions!$B$5,Assumptions!$B$4)+G25*Assumptions!$B$5 -> 544.1635 | N25: =F25*INDEX(Assumptions!$B$8:$B$14,MATCH(E25,Assumptions!$A$8:$A$14,0)) -> 2.8333 | O25: =G25*INDEX(Assumptions!$B$8:$B$14,MATCH(E25,Assumptions!$A$8:$A$14,0)) -> 1.1 | P25: High | Q25: Includes Month-end 2.6, Bookkeeping 0.9. Review = 1.10h as logged (only 2 reviewed close(s) in Harvest – check). | R25: Not settled by rule – median of last 6 months (2026-04 – 2026-09)
A26: BeckShar Development LLC|1099|1099 Quarterly Review|1099 | B26: BeckShar Development LLC | C26: 1099 | D26: 1099 Quarterly Review | E26: 1099 | F26: =IFERROR(INDEX('1099 Oct 30'!$H$5:$H$45,MATCH(B26,'1099 Oct 30'!$A$5:$A$45,0)),0) -> 0.75 | G26: 0 | H26: =F26+G26 -> 0.75 | I26: =ROUND(H26*60,0) -> 45 | J26: =ROUND(F26*60,0) -> 45 | K26: =ROUND(G26*60,0) -> 0 | L26: Staff | M26: =F26*IF(L26="CFO",Assumptions!$B$5,Assumptions!$B$4)+G26*Assumptions!$B$5 -> 71.25 | N26: =F26*INDEX(Assumptions!$B$8:$B$14,MATCH(E26,Assumptions!$A$8:$A$14,0)) -> 0.25 | O26: =G26*INDEX(Assumptions!$B$8:$B$14,MATCH(E26,Assumptions!$A$8:$A$14,0)) -> 0 | P26: Estimate | Q26: 1099 tier Standard: ongoing quarterly review (half a full review). See 1099 tab for the Oct 30 cycle. | R26: Settled from 2026-06 (2026-06 – 2026-09)
A27: BeckShar Development LLC|Monthly Financials|Month End Close|Monthly | B27: BeckShar Development LLC | C27: Monthly Financials | D27: Month End Close | E27: Monthly | F27: 6.9167 | G27: 0.8 | H27: =F27+G27 -> 7.7167 | I27: =ROUND(H27*60,0) -> 463 | J27: =ROUND(F27*60,0) -> 415 | K27: =ROUND(G27*60,0) -> 48 | L27: Staff | M27: =F27*IF(L27="CFO",Assumptions!$B$5,Assumptions!$B$4)+G27*Assumptions!$B$5 -> 857.0865 | N27: =F27*INDEX(Assumptions!$B$8:$B$14,MATCH(E27,Assumptions!$A$8:$A$14,0)) -> 6.9167 | O27: =G27*INDEX(Assumptions!$B$8:$B$14,MATCH(E27,Assumptions!$A$8:$A$14,0)) -> 0.8 | P27: High | Q27: Includes Month-end 2.5, Bookkeeping 0.2, Payroll 1.6, CFO advisory 2.1. Review = median of 6 closes reviewed in Harvest (0.80h). | R27: Settled from 2026-06 (2026-06 – 2026-09)
A28: BeckShar Diamond Commercial LLC|1099|1099 Quarterly Review|1099 | B28: BeckShar Diamond Commercial LLC | C28: 1099 | D28: 1099 Quarterly Review | E28: 1099 | F28: =IFERROR(INDEX('1099 Oct 30'!$H$5:$H$45,MATCH(B28,'1099 Oct 30'!$A$5:$A$45,0)),0) -> 0.75 | G28: 0 | H28: =F28+G28 -> 0.75 | I28: =ROUND(H28*60,0) -> 45 | J28: =ROUND(F28*60,0) -> 45 | K28: =ROUND(G28*60,0) -> 0 | L28: Staff | M28: =F28*IF(L28="CFO",Assumptions!$B$5,Assumptions!$B$4)+G28*Assumptions!$B$5 -> 71.25 | N28: =F28*INDEX(Assumptions!$B$8:$B$14,MATCH(E28,Assumptions!$A$8:$A$14,0)) -> 0.25 | O28: =G28*INDEX(Assumptions!$B$8:$B$14,MATCH(E28,Assumptions!$A$8:$A$14,0)) -> 0 | P28: Estimate | Q28: 1099 tier Standard: ongoing quarterly review (half a full review). See 1099 tab for the Oct 30 cycle. | R28: Settled from 2026-06 (2026-06 – 2026-09)
A29: BeckShar Diamond Commercial LLC|Monthly Financials|Month End Close|Monthly | B29: BeckShar Diamond Commercial LLC | C29: Monthly Financials | D29: Month End Close | E29: Monthly | F29: 0.4167 | G29: 0.5 | H29: =F29+G29 -> 0.9167 | I29: =ROUND(H29*60,0) -> 55 | J29: =ROUND(F29*60,0) -> 25 | K29: =ROUND(G29*60,0) -> 30 | L29: Staff | M29: =F29*IF(L29="CFO",Assumptions!$B$5,Assumptions!$B$4)+G29*Assumptions!$B$5 -> 164.5865 | N29: =F29*INDEX(Assumptions!$B$8:$B$14,MATCH(E29,Assumptions!$A$8:$A$14,0)) -> 0.4167 | O29: =G29*INDEX(Assumptions!$B$8:$B$14,MATCH(E29,Assumptions!$A$8:$A$14,0)) -> 0.5 | P29: High | Q29: Includes Month-end 0.7. Review = median of 4 closes reviewed in Harvest (0.50h). | R29: Settled from 2026-06 (2026-06 – 2026-09)
A30: BeckShar LLC|1099|1099 Quarterly Review|1099 | B30: BeckShar LLC | C30: 1099 | D30: 1099 Quarterly Review | E30: 1099 | F30: =IFERROR(INDEX('1099 Oct 30'!$H$5:$H$45,MATCH(B30,'1099 Oct 30'!$A$5:$A$45,0)),0) -> 2 | G30: 0 | H30: =F30+G30 -> 2 | I30: =ROUND(H30*60,0) -> 120 | J30: =ROUND(F30*60,0) -> 120 | K30: =ROUND(G30*60,0) -> 0 | L30: Staff | M30: =F30*IF(L30="CFO",Assumptions!$B$5,Assumptions!$B$4)+G30*Assumptions!$B$5 -> 190 | N30: =F30*INDEX(Assumptions!$B$8:$B$14,MATCH(E30,Assumptions!$A$8:$A$14,0)) -> 0.66666667 | O30: =G30*INDEX(Assumptions!$B$8:$B$14,MATCH(E30,Assumptions!$A$8:$A$14,0)) -> 0 | P30: Estimate | Q30: 1099 tier Complex: ongoing quarterly review (half a full review). See 1099 tab for the Oct 30 cycle. | R30: Settled from 2026-05 (2026-05 – 2026-09)
A31: BeckShar LLC|Monthly Financials|Month End Close|Monthly | B31: BeckShar LLC | C31: Monthly Financials | D31: Month End Close | E31: Monthly | F31: 2.9167 | G31: 1.25 | H31: =F31+G31 -> 4.1667 | I31: =ROUND(H31*60,0) -> 250 | J31: =ROUND(F31*60,0) -> 175 | K31: =ROUND(G31*60,0) -> 75 | L31: Staff | M31: =F31*IF(L31="CFO",Assumptions!$B$5,Assumptions!$B$4)+G31*Assumptions!$B$5 -> 589.5865 | N31: =F31*INDEX(Assumptions!$B$8:$B$14,MATCH(E31,Assumptions!$A$8:$A$14,0)) -> 2.9167 | O31: =G31*INDEX(Assumptions!$B$8:$B$14,MATCH(E31,Assumptions!$A$8:$A$14,0)) -> 1.25 | P31: High | Q31: Includes Month-end 1.2, Bookkeeping 0.5, Payroll 1.3, Sales tax 0.8. Review = 1.25h as logged (only 2 reviewed close(s) in Harvest – check). | R31: Settled from 2026-05 (2026-05 – 2026-09)
A32: Building and Development Professionals LLC|1099|1099 Quarterly Review|1099 | B32: Building and Development Professionals LLC | C32: 1099 | D32: 1099 Quarterly Review | E32: 1099 | F32: =IFERROR(INDEX('1099 Oct 30'!$H$5:$H$45,MATCH(B32,'1099 Oct 30'!$A$5:$A$45,0)),0) -> 2 | G32: 0 | H32: =F32+G32 -> 2 | I32: =ROUND(H32*60,0) -> 120 | J32: =ROUND(F32*60,0) -> 120 | K32: =ROUND(G32*60,0) -> 0 | L32: Staff | M32: =F32*IF(L32="CFO",Assumptions!$B$5,Assumptions!$B$4)+G32*Assumptions!$B$5 -> 190 | N32: =F32*INDEX(Assumptions!$B$8:$B$14,MATCH(E32,Assumptions!$A$8:$A$14,0)) -> 0.66666667 | O32: =G32*INDEX(Assumptions!$B$8:$B$14,MATCH(E32,Assumptions!$A$8:$A$14,0)) -> 0 | P32: Estimate | Q32: 1099 tier Complex: ongoing quarterly review (half a full review). See 1099 tab for the Oct 30 cycle. | R32: Not settled by rule – median of last 6 months (2026-04 – 2026-09)
A33: Building and Development Professionals LLC|Monthly Financials|Month End Close|Monthly | B33: Building and Development Professionals LLC | C33: Monthly Financials | D33: Month End Close | E33: Monthly | F33: 2.75 | G33: 0.5 | H33: =F33+G33 -> 3.25 | I33: =ROUND(H33*60,0) -> 195 | J33: =ROUND(F33*60,0) -> 165 | K33: =ROUND(G33*60,0) -> 30 | L33: CFO | M33: =F33*IF(L33="CFO",Assumptions!$B$5,Assumptions!$B$4)+G33*Assumptions!$B$5 -> 812.5 | N33: =F33*INDEX(Assumptions!$B$8:$B$14,MATCH(E33,Assumptions!$A$8:$A$14,0)) -> 2.75 | O33: =G33*INDEX(Assumptions!$B$8:$B$14,MATCH(E33,Assumptions!$A$8:$A$14,0)) -> 0.5 | P33: High | Q33: Includes Month-end 0.5, CFO advisory 1.9. Review = 0.5h placeholder (no close reviews found in Harvest) – check. | R33: Not settled by rule – median of last 6 months (2026-04 – 2026-09)
A34: Capital Financial LLC|1099|1099 Quarterly Review|1099 | B34: Capital Financial LLC | C34: 1099 | D34: 1099 Quarterly Review | E34: 1099 | F34: =IFERROR(INDEX('1099 Oct 30'!$H$5:$H$45,MATCH(B34,'1099 Oct 30'!$A$5:$A$45,0)),0) -> 0.75 | G34: 0 | H34: =F34+G34 -> 0.75 | I34: =ROUND(H34*60,0) -> 45 | J34: =ROUND(F34*60,0) -> 45 | K34: =ROUND(G34*60,0) -> 0 | L34: Staff | M34: =F34*IF(L34="CFO",Assumptions!$B$5,Assumptions!$B$4)+G34*Assumptions!$B$5 -> 71.25 | N34: =F34*INDEX(Assumptions!$B$8:$B$14,MATCH(E34,Assumptions!$A$8:$A$14,0)) -> 0.25 | O34: =G34*INDEX(Assumptions!$B$8:$B$14,MATCH(E34,Assumptions!$A$8:$A$14,0)) -> 0 | P34: Estimate | Q34: 1099 tier Standard: ongoing quarterly review (half a full review). See 1099 tab for the Oct 30 cycle. Aug–Sep 2026 excluded (one-time payroll JE re-entry, resolved). | R34: Settled from 2026-03 (2026-03 – 2026-07)
